# 10-async异步函数

## 异步函数（用 async 声明的函数）

### [#](https://web.qianguyihao.com/06-JavaScript基础：异步编程/10-async异步函数.html#异步函数的定义)异步函数的定义

async 关键字用于声明一个异步函数。异步函数总是返回一个 Promise 对象，无论函数内部返回的是普通值还是 Promise。

使用`async`关键字声明的函数，称之为异步函数。在普通函数前面加上 async 关键字，就成了异步函数。语法举例：

```js
// 写法1：函数声明的写法
async function foo1() {
}

// 写法2：表达式写法（ES5语法）
const foo2 = async function () {
}

// 写法3：表达式写法（ES6箭头函数语法）
const foo3 = async () => {
}

// 写法4：定义一个类，在类中添加一个异步函数
class Person {
  async foo4() {
  }
}
```

JS中的“异步函数”是一个专有名词，特指用`async`关键字声明的函数，其他函数则称之为普通函数。如果你在一个普通函数中定义了一个异步任务，那并不叫异步函数，而是叫包含异步任务的普通函数。

async （异步的）这个单词是 asynchronous 的缩写；相反，sync（同步的）这单词是 synchronous 的缩写。

上面的异步函数代码，执行顺序与普通函数相同，默认情况下会同步执行。如果想要发挥异步执行的作用，则需要配合 await 关键字使用。稍后我们再讲 async/await的语法。

## 异步函数的返回值

> 异步函数的返回值和普通函数差别比较大，需要特别关注。

普通函数的返回值，默认是 undefined；也可以手动 return 一个返回值，那就以手动 return的值为准。

**异步函数的返回值永远是 Promise 对象**。至于这个 Promise 后续会进入什么状态，那就要看情况了。主要有以下几种情况：

- 情况1：如果异步函数内部返回的是普通值（包括 return undefined时）或者普通对象，那么Promise 的状态为fulfilled。这个值会作为then()回调的参数。
- 情况2：如果异步函数内部返回的是**另外一个新的 Promise**，那么 Promise 的状态将**交给新的 Promise 决定**。
- 情况3：如果异步函数内部返回的是一个对象，并且这个对象里有实现then()方法（这种对象称为 **thenable** 对象），那就会执行该then()方法，并且根据**then()方法的结果来决定Promise的状态**。

另外还有一种特殊情况：

- 情况4：如果异步函数内部在执行时遇到异常或者手动抛出异常时，那么， Promise 处于rejected 状态。

上面这四种情况似曾相识，我们在前面学习“resolve() 传入的参数”、“then()方法的返回值”知识点时，都有类似的情况，知识都是相通的。

### [#](https://web.qianguyihao.com/06-JavaScript基础：异步编程/10-async异步函数.html#默认返回值)默认返回值

代码举例：

```js
async function foo2() {
  // 相当于 return undefined，也相当于 return Promise.resolve(undefined)
};

async function foo3() {
  Promise.resolve('qianguyihao');
  // 相当于 return undefined，也相当于 return Promise.resolve(undefined)
};

// foo2()、foo3()都是一个Promise对象
foo2().then(res => {
  console.log(res); // 打印结果：undefined
})

foo3().then(res => {
  console.log(res); // 打印结果：undefined
})
```

代码解释：异步函数即便没有手动写返回值，也相当于 `return Promise.resolve(undefined)`。

### 返回普通值

比如下面这段代码：

```js
async function foo() {
  return 'qianguyihao'
};
```

![image-20230608114346235](assets/image-20230608114346235.png)

可以看到，foo() 的返回值是Promise对象，不是字符串。上面的代码等价于下面这段代码：

```js
async function foo() {
  return Promise.resolve('qianguyihao');
};
```

进而，我们可以通过 Promise 对象的then()方法。代码举例如下。

举例1：（异步函数中手动 return 一个值）

```js
async function foo() {
  return 'qianguyihao';
  // 上面这行代码相当于：return Promise.resolve('qianguyihao');
};

// foo() 是一个Promise对象
foo().then(res => {
  console.log(res); // 打印结果：qianguyihao
})
```

## async/await 的使用

### 异步函数配合 await 关键字使用

我们可以在`async`声明的异步函数中，使用 `await`关键字来暂停函数的执行，等待一个异步操作完成。温馨提示：await 关键字不能在普通函数中使用，只能在异步函数中使用。

在等待异步操作期间，异步函数会暂停执行，并让出线程，使其他代码可以继续执行。一旦异步操作完成，该异步函数会恢复执行，并返回一个 Promise 对象。具体解释如下：

（1）await的后面是一个表达式，这个表达式要求是一个 Promise 对象（通常是一个封装了异步任务的Promise对象）。await执行完成后可以得到异步结果。

（2）await 会等到当前 Promise 的状态变为 fulfilled之后，才继续往下执行异步函数。

- async 的返回值是 Promise 对象。

### 本质是语法糖

async/await 是在 ES8(即ES 2017）中引入的新语法，是另外一种异步编程解决方案。

async/await 本质是 生成器 Generator 的语法糖，是对Generator的封装。什么是语法糖呢？语法糖就是让语法变得更加简洁、更加舒服，有一种甜甜的感觉。

async/await 的写法使得编写异步代码更加直观和易于管理，避免了使用回调函数或Promise链的复杂性。认识到这一点，非常重要。

### Promise、Generator、async/await的对比

我们在使用 Promise、async/await、Generator 的时候，返回的都是 Promise 的实例。

如果直接使用 Promise，则需要通过 then 来进行链式调用；如果使用 async/await、Generator，写起来更像同步的代码。

接下来，我们看看 async/await 的代码是怎么写的。

### async/await 的基本用法

async 后面可以跟一个 Promise 实例对象。代码举例如下：

```js
const request1 = function () {
  const promise = new Promise((resolve, reject) => {
    requestAjax('https://www.baidu.com/xxx_url', (res) => {
      if (res.retCode == 200) {
        // 这里的 res 是接口1的返回结果
        resolve('request1 success' + res);
      } else {
        reject('接口请求失败');
      }
    });
  });

  return promise;
};

async function requestData() {
  // 关键代码
  const res = await request1();
  return res;
}
requestData().then(res => {
  console.log(res);
});
```

### 用 async/await 封装Promise链式调用【重要】

假设现在有三个网络请求，请求2必须依赖请求1的结果，请求3必须依赖请求2的结果，如果按照ES5的写法，会有三层回调，会陷入“回调地狱”。

这种场景其实就是接口的多层嵌套调用。之前学过 Promise，它可以把原本的**多层嵌套调用**改进为**链式调用**。

而本文要学习的 async/await ，可以把原本的“多层嵌套调用”改成类似于同步的写法，非常优雅。

代码举例：

```js
// 【公共方法层】封装 ajax 请求的伪代码。传入请求地址、请求参数，以及回调函数 success 和 fail。
function requestAjax(url, params, success, fail) {
  var xhr = new xhrRequest();
  // 设置请求方法、请求地址。请求地址的格式一般是：'https://api.example.com/data?' + 'key1=value1&key2=value2'
  xhr.open('GET', url);
  // 设置请求头（如果需要）
  xhr.setRequestHeader('Content-Type', 'application/json');
  xhr.send();
  xhr.onreadystatechange = function () {
    if (xhr.readyState === 4 && xhr.status === 200) {
      success && success(xhr.responseText);
    } else {
      fail && fail(new Error('接口请求失败'));
    }
  };
}

// 【model层】将接口请求封装为 Promise
function requestData1(params_1) {
  return new Promise((resolve, reject) => {
    requestAjax('https://api.qianguyihao.com/url_1', params_1, res => {
      // 这里的 res 是接口返回的数据。返回码 retCode 为 0 代表接口请求成功。
      if (res.retCode == 0) {
        // 接口请求成功时调用
        resolve('request success' + res);
      } else {
        // 接口请求异常时调用
        reject({ retCode: -1, msg: 'network error' });
      }
    });
  });
}


// requestData2、requestData3的写法与 requestData1类似。他们的请求地址、请求参数、接口返回结果不同，所以需要挨个单独封装 Promise。
function requestData2(params_2) {
  return new Promise((resolve, reject) => {
    requestAjax('https://api.qianguyihao.com/url_2', params_2, res => {
      if (res.retCode == 0) {
        resolve('request success' + res);
      } else {
        reject({ retCode: -1, msg: 'network error' });
      }
    });
  });
}

function requestData3(params_3) {
  return new Promise((resolve, reject) => {
    requestAjax('https://api.qianguyihao.com/url_3', params_3, res => {
      if (res.retCode == 0) {
        resolve('request success' + res);
      } else {
        reject({ retCode: -1, msg: 'network error' });
      }
    });
  });
}

// 封装：用 async ... await 调用 Promise 链式请求
async function getData() {
  // 【关键代码】
  const res1 = await requestData1(params_1);
  const res2 = await requestData2(res1);
  const res3 = await requestData3(res2);
}

getData();
```

### await 后面也可以跟一个异步函数

前面讲到，await后面通常是一个执行异步任务的Promise对象。由于异步函数的返回值本身就是一个Promise，所以，我们也可以在await 后面也可以跟一个异步函数。

代码举例：

```js
const request1 = function () {
  return new Promise((resolve, reject) => {
    resolve('request1 请求成功');
  });
};

async function request2() {
  const res = await request1();
  return res;
}

async function request3() {
  // 【关键代码】request2() 既是一个异步函数，同样也是一个 Promise，所以可以跟在 await 的后面
  const res = await request2();
  console.log('res:', res);
}

request3();
```

## 异步函数的异常处理

前面讲过，如果异步函数内部在执行时遇到异常或者手动抛出异常时，那么， 这个异步函数返回的Promise 处于rejected 状态。

捕获并处理异步函数的异常时，有两种方式：

- 方式1：通过 Promise的catch()方法捕获异常。
- 方式2：通过 try catch捕获异常。

在处理异步函数的异常情况时，方式2更为常见。

如果我们不捕获异常，则会往上层层传递，最终传递给浏览器，浏览器会在控制台报错。

### [#](https://web.qianguyihao.com/06-JavaScript基础：异步编程/10-async异步函数.html#方式1-过-promise的catch-方法捕获异常)方式1：过 Promise的catch()方法捕获异常

```js
function requestData1() {
  return new Promise((resolve, reject) => {
    reject('任务1失败');
  })
}

function requestData2() {
  return new Promise((resolve, reject) => {
    resolve('任务2成功');
  })
}

async function getData() {
  // requestData1 在执行时，遇到异常
  await requestData1();
  /*
  由于上面的代码在执行是遇到异常，所以，这里虽然什么都没写，底层默认写了如下代码：
  return Promise.reject('任务1失败');
  */

  // 下面这行代码不会再走了
  await requestData2();
}

// getData() 这个异步函数的返回值是一个 Promise，状态为 rejected，所以会走到 catch()
getData().then(res => {
  console.log(res);
}).catch(err => {
  console.log('err:', err);
});
```

打印结果：

```text
err: 任务1失败
```

### 方式2：通过 try catch 捕获异常

如果你觉得上面的写法比较麻烦，还可以通过 try catch 捕获异常。

代码举例：

```js
function requestData1() {
  return new Promise((resolve, reject) => {
    reject('任务1失败');
  })
}

function requestData2() {
  return new Promise((resolve, reject) => {
    resolve('任务2成功');
  })
}

async function getData() {
  try {
    // requestData1 在执行时，遇到异常
    await requestData1();
    /*
    由于上面的代码在执行是遇到异常，当前任务立即终止，所以，这里虽然什么都没写，底层默认写了如下代码：
    return Promise.reject('任务1失败');
    */

    // 下面这两代码不会再走了
    console.log('qianguyihao1');
    await requestData2();
  }
  catch (err) {
    // 捕获异常代码
    console.log('err:', err);
  }
}

getData();
console.log('qianguyihao2');
```

打印结果：

```text
qianguyihao2
err1: 任务1失败
```

## 总结

在 async 函数中，不是所有的 异步任务都需要 await。如果两个任务在业务上没有**依赖关系**，则不需要 await；也就是说，可以并发执行，不需要线性执行，避免无用的等待

# 11-异常处理方案

## 异常处理方案

在JS开发中，**处理**异常包括两步：先**抛出**异常，然后**捕获**异常。

###  为什么要做异常处理

异常处理非常重要，至少有以下几个原因：

1. 防止程序报错甚至停止运行：当代码执行过程中发生错误或异常时，如果没有适当的异常处理机制，程序可能会报错、停止运行，甚至崩溃。通过处理异常，我们可以捕获错误并采取适当的措施避免系统报错。
2. 错误排查和调试：异常处理有助于定位和排查错误。可以通过捕获异常并输出相关信息，比如打印日志、错误上报、跟踪堆栈等等，以便快速定位问题所在，并进行调试和修复。
3. 提高代码健壮性和可靠性：可以采取适当的措施处理潜在的异常情况，从而减少程序出错的可能性。
4. 提升用户体验：通过兜底、容错、容灾等异常处理方案，可以向用户提供有效的错误信息提示，而不是让用户界面无响应甚至白屏。

### 抛出异常

抛出异常的使用场景举例：

我们经常会封装一些工具函数，这些函数可能给自己用，也可能给外部团队用。

在函数内部，如果不符合预期的业务逻辑，或者遇到异常情况时，很多人的写法是直接 return，不往下执行了。但是 return 的写法存在一个很大的弊端：**调用者不知道是因为函数内部没有正常执行，还是执行的返回结果就是一个undefined**。return 的写法只是规避了问题，没有解决问题。建议的做法是：我们**需要手动抛出异常**。

### 捕获异常

如果只是抛出异常，而不捕获异常的话，是比较危险的。这意味着当前任务立即终止，不再执行（当然，后续的其他任务会正常执行）。此外，这个异常信息会层层往上，抛给上层的**调用者**。如果一直未被捕获，则最终会抛给**浏览器**，浏览器控制台就会报错。

接下来，我们看一下不同代码场景下的异常处理方案。

### 上报异常

如果有必要的话，你可以把异常信息和日志，上报给监控服务器，然后集中分析。我每天上班第一件事，就是打开监控系统，看错误日志，然后对症下药解决问题。

## 同步代码的异常处理

### 通过 throw 抛出异常

我们可以通过 `throw`关键字，抛出一个**用户自定义**的异常。当代码执行时遇到 throw 语句时，当前函数会停止停止，即：**当前函数** throw 后面的代码不会再执行。

throw 意思是，告诉调用者，当前被调用的函数报错了，调用者接下来需要捕获异常或者修改代码逻辑。

可以在 throw 的后面添加表达式或者数据类型，将添加的内容抛出去。数据类型可以是：number、string、boolean、对象等。

代码举例：

```js
function sum(num1, num2) {
  if (typeof num1 !== "number") {
    throw "type error: num1传入的类型有问题, 必须是number类型"
  }

  if (typeof num2 !== "number") {
    throw "type error: num2传入的类型有问题, 必须是number类型"
  }

  return num1 + num2
}

sum('a', 'b');
```

打印结果：

![image-20230608180755608](assets/image-20230608180755608.png)

当然，我们还可以 throw一个封装好的对象。比如：

```js
class myError {
  constructor(errCode, errMsg) {
    this.errCode = errMsg;
    this.errMsg = errMsg;
  }
}

function foo() {
  throw new myError(-1, 'not login');
}

foo();
```

上面这种写法比较麻烦，一般不这么写。其实，JS中已经内置了 Error 类，专门用于生成错误信息。

### Error 类

JS内置的 Error 类非常好用。

代码举例：

```js
function foo() {
  throw new Error('not login');
}


foo();
```

打印结果：

![image-20230608180103263](assets/image-20230608180103263.png)

上面的打印结果可以看到，通过 Error 抛出来的错误，不仅可以看到报错信息，还可以看到调用栈，便于快速定位问题所在。非常方便。

### 通过 try catch 捕获异常

同步代码，只抛出异常，不捕获异常的代码举例：

```js
function foo() {
  throw new Error('not login');
}

foo();
// 当前任务立即终止，不再执行；下面这行代码和 foo() 都在同一个 同步任务 中
console.log('qianguyihao');
```

打印结果：

![image-20230608182003407](assets/image-20230608182003407.png)

可以看到，最后一行的 log 并没有执行。

我们可以使用 try catch 抛出异常， 对上述代码进行改进。代码举例：

```js
function foo() {
  throw new Error('not login');
}

// 通过 try catch 手动捕获异常
try {
  foo();
} catch (err) {
  console.log(err);
}

// 当前任务的后续代码会继续执行
console.log('qianguyihao');
```

打印结果：

![image-20230608182140002](assets/image-20230608182140002.png)

### [#](https://web.qianguyihao.com/06-JavaScript基础：异步编程/11-异常处理方案.html#通过-try-catch-finally-捕获异常)通过 try catch finally 捕获异常

如果有些代码必须要执行，我们可以放到 finally 里。

- 不管是否遇到异常，finally的代码一定会执行。
- 如果 try 和 finally 中都有返回值，那么会使用finally中的返回值。

代码举例：

```js
function foo() {
  throw new Error('not login');
}

// 通过 try catch 捕获异常
try {
  foo();
} catch (err) {
  console.log(err);
} finally {
  console.log("finally")
}

// 后续代码会继续执行
console.log('qianguyihao');
```

### try catch 只能捕获同步代码的异常

try catch只能捕获同步代码里的异常，而 Promise.reject() 是异步代码。

原因是：当异步函数抛出异常时，对于宏任务而言，执行函数时已经将该函数推入栈，此时并不在 try-catch 所在的栈，所以 try-catch 并不能捕获到错误。对于微任务而言（比如 promise）promise 的构造函数的异常只能被自带的 reject 也就是.catch 函数捕获到。

### 使用 window.onerror 监听未被捕获的代码异常

如果JS代码抛出了异常但没有进行捕获，我们可以使用 JS 自带的 `window.onerror` 事件监听到这些错误。

代码举例：

```js
// 监听同步代码的异常
window.onerror = (event) => {
  console.error('onerror 监听到未被捕获的异常:', event)
};

function foo1() {
  throw new Error('not login');
}

function foo2() {
  throw new Error('network error');
}

foo1();
foo2();
```

打印结果：

![image-20230624162123559](assets/image-20230624162123559.png)

>foo1 执行，抛出 new Error('not login')。
>
>由于没有 try/catch 包裹，错误未被捕获，冒泡到全局。
>
>window.onerror 被触发

## Promise 的异常处理

### reject() 会自动抛出异常

在使用 Promise 时，当我们调用了 reject() 之后，系统会**自动抛出异常**，不需要我们手动抛出异常。这是 Promise的内部机制。但是我们需要手动捕获异常。

当 Promise 进入 rejected状态之后，会触发 catch()方法的执行，捕获异常。此时，成功完成了Promise异常处理的闭环。

### 在then() 中抛出异常（重要）

当then()方法传入的回调函数中，如果遇到异常或者手动抛出异常，那么，then()所返回的**新的 Promise 会进入rejected 状态**，进而触发新Promise 的 catch() 方法的执行，做异常捕获。

**场景1**：在then()方法传入的回调函数中，如果代码**在执行时遇到异常**，系统会**自动抛出异常**。此时我们需要在 catch() 里**手动捕获异常**，否则会报错。

自动抛出异常的代码举例：（由于没有捕获异常，所以会报错）

```js
const myPromise = new Promise((resolve, reject) => {
  resolve('qianguyihao1 fulfilled');
});

myPromise.then(res => {
  console.log('res1:', res);
  // 显然，person 并没有 forEach()方法。所以，代码在执行时，会遇到异常。
  const person = { name: 'vae' };
  person.forEach(item => {
    console.log('item:', item);
  })
  // 这行代码不会执行，因为上面的代码报错了
  console.log('qianguyihao2');
}).then(res => {
  console.log('res2:', res);
})

// 定时器里的代码正常执行
setTimeout(() => {
  console.log('qianguyihao3');
}, 100)
```

运行结果：

![image-20230615090007932](assets/image-20230615090007932.png)

代码改进：（代码在执行时遇到异常，此时我们捕获异常，所以系统不会报错，这才是推荐的写法）

```js
const myPromise = new Promise((resolve, reject) => {
  resolve('qianguyihao1 fulfilled');
});

myPromise.then(res => {
  console.log('res1:', res);
  // 显然，person 并没有 forEach()方法。所以，代码在执行时，会遇到异常。
  const person = { name: 'vae' };
  person.forEach(item => {
    console.log('item:', item);
  })
  // 这行代码不会执行，因为上面的代码报错了
  console.log('qianguyihao2');
}).then(res => {
  console.log('res2:', res);
}).catch(err => {
  // 在 catch()方法传入的会调函数里，捕获异常
  console.log('err2:', err);
})

// 定时器里的代码正常执行
setTimeout(() => {
  console.log('qianguyihao3');
}, 100)
```

打印结果：

![image-20230624072927944](assets/image-20230624072927944.png)

**场景2**：在then()方法传入的回调函数中，如果我们手动抛出异常，此时我们需要在 catch() 里**手动捕获异常**，否则会报错。

代码举例：（手动抛出异常，未捕获，所以会报错）

```js
const myPromise = new Promise((resolve, reject) => {
  resolve('qianguyihao fulfilled 1');
});

myPromise.then(res => {
  console.log('res1:', res);
  // 手动抛出异常
  throw new Error('qianguyihao rejected 2')
}).then(res => {
  console.log('res2:', res);
})

// 定时器里的代码正常执行
setTimeout(() => {
  console.log('qianguyihao3');
}, 100)
```

打印结果：

![image-20230624073252797](assets/image-20230624073252797.png)

代码改进：（代码在执行时遇到异常，此时我们捕获异常，所以系统不会报错，这才是推荐的写法）

```js
const myPromise = new Promise((resolve, reject) => {
  resolve('qianguyihao fulfilled 1');
});

myPromise.then(res => {
  console.log('res1:', res);
  // 手动抛出异常
  throw new Error('qianguyihao rejected 2')
}).then(res => {
  console.log('res2:', res);
}, (err) => {
  console.log('err2:', err);
})

// 定时器里的代码正常执行
setTimeout(() => {
  console.log('qianguyihao3');
}, 100)
```

打印结果：

![image-20230624073604599](assets/image-20230624073604599.png)

### [#](https://web.qianguyihao.com/06-JavaScript基础：异步编程/11-异常处理方案.html#使用-unhandledrejection-事件监听未被捕获的promise异常)使用 unhandledrejection 事件监听未被捕获的Promise异常

如果Promise抛出了异常但没有进行捕获，我们可以使用JS自带的 `unhandledrejection` 事件监听到这些错误。这个事件非常有用，尤其是当我们需要**集中做日志收集**时，屡试不爽。这个事件只能用于监听 Promise 中的异常，不能用于其他同步代码的异常。

先来看下面这行代码：

```js
const myPromise = new Promise((resolve, reject) => {
  console.log('qianguyihao1');
  reject('not login');
  console.log('qianguyihao2');
})
```

打印结果：

![image-20230624154609747](assets/image-20230624154609747.png)

上面的代码抛出了异常，但没有捕获异常，所以我们可以用 unhandledrejection 事件监听到。代码举例：

```js
// 监听未被捕获的 Promise 异常
window.addEventListener('unhandledrejection', (event) => {
  console.error(`unhandledrejection 监听到异常，写法1: ${event.reason}`)
});

window.onunhandledrejection = event => {
  console.error(`unhandledrejection 监听到异常，写法2: ${event.reason}`);
};

window.onerror = (event) => {
  console.error('onerror 监听到异常:', event);
};


const promise1 = new Promise((resolve, reject) => {
  reject('not login');
})

const promise2 = new Promise((resolve, reject) => {
  throw new Error('network error');
  resolve();
})
```

打印结果：

![image-20230624172634569](assets/image-20230624172634569.png)

可以看到，promise1 和 Promise2 的异常，都被 unhandledrejection 事件**收集**到了。

代码举例2：

```js
window.addEventListener('unhandledrejection', (event) => {
  console.error(`unhandledrejection 监听到异常: ${event.reason}`)
});

window.onerror = (event) => {
  console.error('onerror 监听到异常:', event);
};

const myPromise = new Promise((resolve, reject) => {
  setTimeout(() => {
    throw new Error('not login');
    resolve();
  }, 100);
})
```

打印结果：

![image-20230624172350994](assets/image-20230624172350994.png)

上面的代码中，unhandledrejection 无法监听异常，因为定时器里的代码属于宏任务。

### [#](https://web.qianguyihao.com/06-JavaScript基础：异步编程/11-异常处理方案.html#resolve-之后-再报错无效)resolve()之后，再报错无效

代码举例：

```js
const myPromise = new Promise((resolve, reject) => {
  resolve('fulfilled');
  throw new Error("自定义错误");
});

myPromise.then(res => {
  console.log("res", res);
  return res + 1;
}).catch(err => {
  console.log("err：", err);
});
```

打印结果：

```js
res fulfilled
```

上方代码中，第3行的异常代码相当于没写。因为 resolve()之后，Promise的状态会立即进入 fulfilled，然后走到 then()，状态不可逆。

## async await 的异常处理

### [#](https://web.qianguyihao.com/06-JavaScript基础：异步编程/11-异常处理方案.html#捕获异常-2)捕获异常

代码举例：

```js
function requestData1() {
  return new Promise((resolve, reject) => {
    reject('任务1失败');
  })
}

function requestData2() {
  return new Promise((resolve, reject) => {
    resolve('任务2成功');
  })
}

async function getData() {
  // requestData1 在执行时，遇到异常
  await requestData1();
  /*
  由于上面的代码在执行是遇到异常，所以，这里虽然什么都没写，底层默认写了如下代码：
  return Promise.reject('任务1失败');
  */

  // 下面这两行代码不会再执行了，因为上面的代码遇到了异常
  console.log('qianguyihao1');
  await requestData2();
}

getData();

// 【注意】定时器里的代码会正常实行，因为它在另外一个宏任务里，不在上面的微任务里
setTimeout(() => {
  console.log('qianguyihao2');
}, 100)
```

打印结果：

![image-20230615085743284](assets/image-20230615085743284.png)

所以，为了避免上述问题，我们还需要手动捕获异常。我们捕获到异常之后，这个异常就不会继续网上抛了，更不会抛给浏览器。

# 12-事件循环机制、宏任务和微任务

## 浏览器的事件循环机制（重要）

![image-20230608154453933](assets/image-20230608154453933.png)

执行顺序如下：

- 同步任务：进入主线程后，立即执行。
- 异步任务：会先进入 Event Table；等时间到了之后，再进入 任务队列 （Event Queue）排队（排队是因为同一时间，JS 只能执行一个任务），先进先出。比如说，`setTimeout(()=> {}, 1000)`这种定时器任务，需要等一秒之后再进入 Event Queue。
- 当主线程的任务执行完毕之后，此时主线程处于空闲状态，于是会去读取 Event Queue 中的任务队列，如果有任务，则进入到主线程去执行。

## Node.js 事件循环机制

浏览器的 EventLoop 依据的是 HTML5 规范。而 Node.js 的 EventLoop 是由Node.js底层的 libuv 规定的。 libuv是一个专注于异步IO的跨平台库。

Node.js的事件循环中，有六个队列。其中，微任务有两个队列，宏任务有四个队列。

一、微任务队列：

- 顺序1：next tick queue。比如：process.nextTick
- 顺序2：other queue。比如：Promise的then回调、queueMicrotask

二、宏任务队列：

- 顺序3：timer queue。比如：setTimeout、setInterval
- 顺序4：poll queue。比如：IO事件
- 顺序5：check queue。比如：setImmediate
- 顺序6：close queue。比如：close事件

参考链接：

- 【荐】浏览器及nodeJS中的EventLoop事件循环机制：https://www.cnblogs.com/weiyongchao/p/13766429.html
- 浏览器和Node 事件循环的区别：https://github.com/Advanced-Frontend/Daily-Interview-Question/issues/26

## 宏任务和微任务

JS中的任务分为同步任务、异步任务。

JS中的异步任务分为宏任务（macrotask）、微任务（microtask）。在早期，异步任务中只有宏任务，没有微任务。后来的语言标准中，推出了“微任务”，因为**希望微任务能够尽早执行**。

### 宏任务、微任务分类

事件循环的队列中，有两个队列。

1、**宏任务队列**，包含这些任务：

- ajax 网络请求
- setTimeout、setInterval
- DOM事件
- UI渲染
- I/O文件读写操作。

2、**微任务队列**，包含这些任务：

- Promise的then回调
- Mutation Observer API：监听DOM节点变化。
- queueMicrotask()：可直接将某个任务加入到微任务队列中。

在执行一个 Promise 对象时，当走完 resolve() 进入 fulfilled状态后，会立刻把 `.then()`里面的代码加入到**微任务队列**当中。

### [#](https://web.qianguyihao.com/06-JavaScript基础：异步编程/12-事件循环机制、宏任务和微任务.html#任务的执行顺序)任务的执行顺序

JS中的任务执行顺序：**同步任务 --> 微任务 --> 宏任务**。

在执行任何一个宏任务之前（不是队列，是一个宏任务），都会**先查询微任务队列中是否还有任务需要执行**：

- 当前宏任务执行之前，必须要保证微任务队列是空的。
- 如果微任务队列不为空，那就优先执行微任务队列中的任务。

## [#](https://web.qianguyihao.com/06-JavaScript基础：异步编程/12-事件循环机制、宏任务和微任务.html#任务执行顺序的面试题)任务执行顺序的面试题

实际开发中，基本不会出现下面这些题目，因为很多时候我们无法精准控制异步任务的执行顺序。但是它们在面试中出现的频率特别高，因为熟悉这些思维训练，有利于考察我们对JS单线程、事件循环机制、宏任务和微任务等原理的掌握程度。

### [#](https://web.qianguyihao.com/06-JavaScript基础：异步编程/12-事件循环机制、宏任务和微任务.html#题-1-宏任务和微任务的执行顺序)题 1：宏任务和微任务的执行顺序

```js
setTimeout(() => {
  // 宏任务
  console.log('setTimeout');
}, 0);

//同步代码
new Promise((resolve, reject) => {
  resolve();
  console.log('promise1'); // 同步任务
}).then((res) => {
  // 微任务
  console.log('promise then');
});

console.log('同步任务'); // 同步任务
```

上方代码执行的顺序依次是：**同步任务 --> 微任务 --> 宏任务**。

### 题 2：在宏任务中嵌套了微任务

```js
new Promise((resolve, reject) => {
  setTimeout(() => {
    resolve();
    console.log('setTimeout'); // 宏任务
  }, 0);
  console.log('promise1');
}).then((res) => {
  // 微任务
  console.log('promise then');
});

console.log('同步任务');
```

打印结果：

```text
promise1
同步任务
setTimeout
promise then
```

上方代码解释：在执行宏任务的**过程中**，创建了一个微任务。但是需要**先把当前这个宏任务执行完**，再去**创建并执行**微任务。

### [#](https://web.qianguyihao.com/06-JavaScript基础：异步编程/12-事件循环机制、宏任务和微任务.html#题3-综合题)题3：综合题

```js
console.log("script start")

setTimeout(() => {
  console.log("setTimeout1");
  new Promise(resolve => {
    resolve();
  }).then(() => {
    new Promise(resolve => {
      resolve();
    }).then(() => {
      console.log("then1");
    });
    console.log("then2");
  });
});

new Promise(resolve => {
  // 下面这两行代码，即便调换顺序，也不影响打印结果
  console.log("promise1");
  resolve();
}).then(() => {
  console.log("then3");
});

setTimeout(() => {
  console.log("setTimeout2");
});

console.log('同步代码');

queueMicrotask(() => {
  console.log("queueMicrotask")
});

new Promise(resolve => {
  resolve();
}).then(() => {
  console.log("then4");
});

console.log("script end");
```

打印结果：

```text
// 第一次循环
script start
promise1
同步代码
script end

// 第二次循环
then3
queueMicrotask
then4

// 第三次循环
setTimeout1
then2
then1

// 第四次循环
setTimeout2
```

### 题4：async await 题目

代码举例：

```js
console.log('script start')

async function async2() {
  console.log('async2')
}

async function async1() {
  console.log('async1 start')
  await async2();
  console.log('async1 end')
}

setTimeout(() => {
  console.log('setTimeout')
}, 0)

async1();

new Promise(resolve => {
  console.log('promise1')
  resolve();
}).then(function () {
  console.log('then1')
})

console.log('script end');
```

打印结果

```text
script start
async1 start
async2
promise1
script end

async1 end
then1

setTimeout
```

# Node.js 中的util.promisify()方法

## Node.js 中的util.promisify()方法

Node.js 中有一个内置的方法 util.promisify()，它可以很方便地将 ES5回调函数写法的方法，转成Promise写法的方法。就不需要我们手动封装Promise了。

代码举例：

```js
// 引入 util 模块
const util = require('util');
// 引入 fs 模块
const fs = require('fs');

// 返回一个新的函数，这个函数是一个 Promise 对象
const readFilePromise = util.promisify(fs.readFile);
readFilePromise('readme.txt').then(res => {
  console.log('res:', res.toString());
});
```

## 使用 Promise 封装定时器，实现延迟函数

代码举例：

```js
// 方法：XX秒后执行指定的代码。这个方法，就是在宏任务（定时器）的执行过程中，创建了一个微任务（resolve）
function delaySeconds(delay = 1000) {
    return new Promise((resolve) => setTimeout(resolve, delay));
}

delaySeconds(2000)
    .then(() => {
        console.log('qiangu');
        return delaySeconds(3000);
    })
    .then(() => {
        console.log('yihao');
    });
```

打印结果：

```js
// 2秒后打印：
qiangu

// 再等3秒后打印：
yihao
```